- [官方文档 - 内置异常](https://docs.python.org/zh-cn/3.7/library/exceptions.html?highlight=exception#Exception)
- [官方教程 - 错误和异常](https://docs.python.org/zh-cn/3.7/tutorial/errors.html#tut-userexceptions)

```python
import sys

def test1():
    raise ValueError('AAAAA')

def test2():
    try:
        test1()
    except Exception as e1:
        tb = sys.exc_info()[2]
        raise e1 from TypeError('BBBBB').with_traceback(tb)

def main():
    test2()

try:
    main()
except Exception as e:
    print(e.__class__, e)
    print(e.args)
    print(e.__cause__.__traceback__.tb_lineno)
    print(e.__suppress_context__)
    print(e.__context__)
    print(e.__traceback__.tb_frame)
    print(e.__traceback__.tb_lineno)
```

使用traceback模块

```python
import sys
import traceback

def test1():
    raise ValueError('AAAAA')

def test2():
    try:
        test1()
    except Exception as e1:
        tb = sys.exc_info()[2]
        raise e1 from TypeError('BBBBB').with_traceback(tb)

def main():
    test2()

try:
    main()
except Exception as e:
    print(traceback.format_exc(limit=2, chain=False))
```



```python
import traceback

def test2():
    raise TypeError('abc')

def main():
    test2()

try:
    main()
except Exception as e:
    for frame, lineno in traceback.walk_tb(e.__traceback__):
        print(frame.f_code.co_name)
```